Workbook
Name ChartClose: INDEX(Multiples!PxClose,MIN('[1]Stock Price'!$I$9,COUNT(Multiples!PxDates))):INDEX(Multiples!PxClose,MAX('[1]Stock Price'!$I$10,1))
Name ChartClose: INDEX(PxClose,MIN('Stock Price'!$I$9,COUNT(PxDates))):INDEX(PxClose,MAX('Stock Price'!$I$10,1))
Name ChartDates: INDEX(Multiples!PxDates,MIN('[1]Stock Price'!$I$9,COUNT(Multiples!PxDates))):INDEX(Multiples!PxDates,MAX('[1]Stock Price'!$I$10,1))
Name ChartDates: INDEX(PxDates,MIN('Stock Price'!$I$9,COUNT(PxDates))):INDEX(PxDates,MAX('Stock Price'!$I$10,1))
Name PeerPct_ABBV: INDEX('[1]Peer Data'!$Z$5:$Z$1258,MIN('[1]Stock Price'!$I$9,1254)):INDEX('[1]Peer Data'!$Z$5:$Z$1258,MAX('[1]Stock Price'!$I$10,1))
Name PeerPct_ABBV: INDEX('Peer Data'!$Z$5:$Z$1258,MIN('Stock Price'!$I$9,1254)):INDEX('Peer Data'!$Z$5:$Z$1258,MAX('Stock Price'!$I$10,1))
Name PeerPct_AZN: INDEX('[1]Peer Data'!$Q$5:$Q$1258,MIN('[1]Stock Price'!$I$9,1254)):INDEX('[1]Peer Data'!$Q$5:$Q$1258,MAX('[1]Stock Price'!$I$10,1))
Name PeerPct_AZN: INDEX('Peer Data'!$Q$5:$Q$1258,MIN('Stock Price'!$I$9,1254)):INDEX('Peer Data'!$Q$5:$Q$1258,MAX('Stock Price'!$I$10,1))
Name PeerPct_BAYNr: INDEX('[1]Peer Data'!$U$5:$U$1258,MIN('[1]Stock Price'!$I$9,1254)):INDEX('[1]Peer Data'!$U$5:$U$1258,MAX('[1]Stock Price'!$I$10,1))
Name PeerPct_BAYNr: INDEX('Peer Data'!$T$5:$T$1258,MIN('Stock Price'!$I$9,1254)):INDEX('Peer Data'!$T$5:$T$1258,MAX('Stock Price'!$I$10,1))
Name PeerPct_BMY: INDEX('[1]Peer Data'!$X$5:$X$1258,MIN('[1]Stock Price'!$I$9,1254)):INDEX('[1]Peer Data'!$X$5:$X$1258,MAX('[1]Stock Price'!$I$10,1))
Name PeerPct_BMY: INDEX('Peer Data'!$X$5:$X$1258,MIN('Stock Price'!$I$9,1254)):INDEX('Peer Data'!$X$5:$X$1258,MAX('Stock Price'!$I$10,1))
Name PeerPct_GSK: INDEX('[1]Peer Data'!$R$5:$R$1258,MIN('[1]Stock Price'!$I$9,1254)):INDEX('[1]Peer Data'!$R$5:$R$1258,MAX('[1]Stock Price'!$I$10,1))
Name PeerPct_GSK: INDEX('Peer Data'!$R$5:$R$1258,MIN('Stock Price'!$I$9,1254)):INDEX('Peer Data'!$R$5:$R$1258,MAX('Stock Price'!$I$10,1))
Name PeerPct_JnJ: INDEX('[1]Peer Data'!$Y$5:$Y$1258,MIN('[1]Stock Price'!$I$9,1254)):INDEX('[1]Peer Data'!$Y$5:$Y$1258,MAX('[1]Stock Price'!$I$10,1))
Name PeerPct_JnJ: INDEX('Peer Data'!$Y$5:$Y$1258,MIN('Stock Price'!$I$9,1254)):INDEX('Peer Data'!$Y$5:$Y$1258,MAX('Stock Price'!$I$10,1))
Name PeerPct_LLY: INDEX('[1]Peer Data'!$W$5:$W$1258,MIN('[1]Stock Price'!$I$9,1254)):INDEX('[1]Peer Data'!$W$5:$W$1258,MAX('[1]Stock Price'!$I$10,1))
Name PeerPct_LLY: INDEX('Peer Data'!$W$5:$W$1258,MIN('Stock Price'!$I$9,1254)):INDEX('Peer Data'!$W$5:$W$1258,MAX('Stock Price'!$I$10,1))
Name PeerPct_MRK: INDEX('[1]Peer Data'!$O$5:$O$1258,MIN('[1]Stock Price'!$I$9,1254)):INDEX('[1]Peer Data'!$O$5:$O$1258,MAX('[1]Stock Price'!$I$10,1))
Name PeerPct_MRK: INDEX('Peer Data'!$U$5:$U$1258,MIN('Stock Price'!$I$9,1254)):INDEX('Peer Data'!$U$5:$U$1258,MAX('Stock Price'!$I$10,1))
Name PeerPct_NVS: INDEX('[1]Peer Data'!$P$5:$P$1258,MIN('[1]Stock Price'!$I$9,1254)):INDEX('[1]Peer Data'!$P$5:$P$1258,MAX('[1]Stock Price'!$I$10,1))
Name PeerPct_NVS: INDEX('Peer Data'!$P$5:$P$1258,MIN('Stock Price'!$I$9,1254)):INDEX('Peer Data'!$P$5:$P$1258,MAX('Stock Price'!$I$10,1))
Name PeerPct_PFE: INDEX('[1]Peer Data'!$V$5:$V$1258,MIN('[1]Stock Price'!$I$9,1254)):INDEX('[1]Peer Data'!$V$5:$V$1258,MAX('[1]Stock Price'!$I$10,1))
Name PeerPct_PFE: INDEX('Peer Data'!$V$5:$V$1258,MIN('Stock Price'!$I$9,1254)):INDEX('Peer Data'!$V$5:$V$1258,MAX('Stock Price'!$I$10,1))
Name PeerPct_ROG: INDEX('[1]Peer Data'!$S$5:$S$1258,MIN('[1]Stock Price'!$I$9,1254)):INDEX('[1]Peer Data'!$S$5:$S$1258,MAX('[1]Stock Price'!$I$10,1))
Name PeerPct_ROG: INDEX('Peer Data'!$O$5:$O$1258,MIN('Stock Price'!$I$9,1254)):INDEX('Peer Data'!$O$5:$O$1258,MAX('Stock Price'!$I$10,1))
Name PeerPct_SNY: INDEX('[1]Peer Data'!$T$5:$T$1258,MIN('[1]Stock Price'!$I$9,1254)):INDEX('[1]Peer Data'!$T$5:$T$1258,MAX('[1]Stock Price'!$I$10,1))
Name PeerPct_SNY: INDEX('Peer Data'!$S$5:$S$1258,MIN('Stock Price'!$I$9,1254)):INDEX('Peer Data'!$S$5:$S$1258,MAX('Stock Price'!$I$10,1))
Name PxClose: '[1]Stock Price'!$E$5:INDEX('[1]Stock Price'!$E:$E,COUNT('[1]Stock Price'!$A:$A)+4)
Name PxClose: 'Stock Price'!$E$5:INDEX('Stock Price'!$E:$E,COUNT('Stock Price'!$A:$A)+4)
Name PxDates: '[1]Stock Price'!$A$5:INDEX('[1]Stock Price'!$A:$A,COUNT('[1]Stock Price'!$A:$A)+4)
Name PxDates: 'Stock Price'!$A$5:INDEX('Stock Price'!$A:$A,COUNT('Stock Price'!$A:$A)+4)

Sheet Stock Price
A1: Roche Holding AG (RHHBY ADR) - Daily Stock Price, Last 5 Years
A2: Source: Yahoo Finance (finance.yahoo.com/quote/RHHBY), retrieved 2026-10-05. USD per ADR (OTCQX). Yahoo close prices are split-adjusted, not dividend-adjusted. The 2026-10-05 session was still open and is excluded. | H2: Price Chart
A4: Date | B4: Open ($) | C4: High ($) | D4: Low ($) | E4: Close ($) | F4: Volume (shares) | H4: Start Date | I4: 44474 | J4: Enter a date (yellow cells are inputs)
A5: 44474 | B5: 46.9 | C5: 47.06 | D5: 46.65 | E5: 46.7 | F5: 1801800 | H5: End Date | J5: Leave blank to use today
A6: 44475 | B6: 46.84 | C6: 47.35 | D6: 46.66 | E6: 47.23 | F6: 795100
A7: 44476 | B7: 47.89 | C7: 48.19 | D7: 47.83 | E7: 48.05 | F7: 1162300 | H7: Calculations
A8: 44477 | B8: 48.38 | C8: 49.92 | D8: 48.3 | E8: 49.89 | F8: 2660300 | H8: End date used | I8: =IF(ISBLANK(I5),TODAY(),I5) -> 46300
A9: 44480 | B9: 48.95 | C9: 49.11 | D9: 48.8 | E9: 48.83 | F9: 729100 | H9: Start row # | I9: =COUNTIF(PxDates,"<"&I4)+1 -> 1
A10: 44481 | B10: 48.33 | C10: 48.36 | D10: 48.07 | E10: 48.23 | F10: 635900 | H10: End row # | I10: =COUNTIF(PxDates,"<="&I8) -> 1254
A11: 44482 | B11: 48.12 | C11: 48.41 | D11: 48.11 | E11: 48.22 | F11: 527100 | H11: Check | I11: =IF(NOT(ISNUMBER(I4)),"Enter a start date",IF(I4>I8,"Start date must be on or before end date",IF(I9>I10,"No trading days between these dates","OK"))) -> OK
A12: 44483 | B12: 48.2 | C12: 48.45 | D12: 48.14 | E12: 48.25 | F12: 347100 | H12: First trading day | I12: =IF($I$11="OK",INDEX(PxDates,I9),"") -> 44474
A13: 44484 | B13: 48.39 | C13: 48.93 | D13: 48.37 | E13: 48.92 | F13: 473500 | H13: Last trading day | I13: =IF($I$11="OK",INDEX(PxDates,I10),"") -> 46297
A14: 44487 | B14: 49.01 | C14: 49.26 | D14: 48.86 | E14: 49.16 | F14: 718200 | H14: Start close ($) | I14: =IF($I$11="OK",INDEX(PxClose,I9),"") -> 46.7
A15: 44488 | B15: 48.12 | C15: 48.7 | D15: 48.11 | E15: 48.55 | F15: 609500 | H15: End close ($) | I15: =IF($I$11="OK",INDEX(PxClose,I10),"") -> 52.25
A16: 44489 | B16: 48 | C16: 48.24 | D16: 47.7 | E16: 47.76 | F16: 1004800 | H16: % change | I16: =IF($I$11="OK",I15/I14-1,"") -> 0.11884368
A17: 44490 | B17: 48.49 | C17: 48.91 | D17: 48.31 | E17: 48.84 | F17: 695600
A18: 44491 | B18: 48.26 | C18: 48.79 | D18: 48 | E18: 48.74 | F18: 1020100 | H18: =IF($I$11<>"OK",$I$11,"RHHBY "&IF(I16>=0,"rose ","fell ")&TEXT(ABS(I16),"0.0%")&" from "&TEXT(I14,"$#,##0.00")&" on "&TEXT(I12,"mmm d, yyyy")&" to "&TEXT(I15,"$#,##0.00")&" on "&TEXT(I13,"mmm d, yyyy")&".") -> RHHBY rose 11.9% from $46.70 on Oct 5, 2021 to $52.25 on Oct 2, 2026.
A19: 44494 | B19: 48.57 | C19: 48.7 | D19: 48.26 | E19: 48.48 | F19: 483300
A20: 44495 | B20: 48.17 | C20: 48.63 | D20: 48.17 | E20: 48.53 | F20: 592600
A21: 44496 | B21: 48.54 | C21: 48.57 | D21: 48.04 | E21: 48.04 | F21: 633300
A22: 44497 | B22: 48.87 | C22: 48.89 | D22: 48.37 | E22: 48.75 | F22: 588200
A23: 44498 | B23: 48.3 | C23: 48.53 | D23: 48.24 | E23: 48.33 | F23: 415700
A24: 44501 | B24: 48.79 | C24: 49.39 | D24: 48.7 | E24: 49.34 | F24: 505300
A25: 44502 | B25: 49.94 | C25: 50.36 | D25: 49.78 | E25: 50.07 | F25: 662200
A26: 44503 | B26: 50.2 | C26: 50.65 | D26: 50.09 | E26: 50.45 | F26: 675000
A27: 44504 | B27: 50.95 | C27: 51.05 | D27: 50.56 | E27: 51.02 | F27: 2257300
A28: 44505 | B28: 49.9 | C28: 50.32 | D28: 49.8 | E28: 50.2 | F28: 945800
A29: 44508 | B29: 50.2 | C29: 50.35 | D29: 50.01 | E29: 50.21 | F29: 673600
A30: 44509 | B30: 50.45 | C30: 50.49 | D30: 50.19 | E30: 50.43 | F30: 484600
... A45: 44531 | B45: 49.34 | C45: 49.87 | D45: 49.13 | E45: 49.14 | F45: 537100
A46: 44532 | B46: 49.51 | C46: 49.58 | D46: 49.25 | E46: 49.52 | F46: 575400 | U46: Peer Comps
A47: 44533 | B47: 49.84 | C47: 49.94 | D47: 49.08 | E47: 49.35 | F47: 556900 | U47: =IF($I$11="OK",TEXT($I$12,"yyyy-mm-dd")&" to "&TEXT($I$13,"yyyy-mm-dd"),$I$11) -> 2021-10-05 to 2026-10-02
A48: 44536 | B48: 50 | C48: 50.14 | D48: 49.56 | E48: 49.73 | F48: 444600 | U48: Ticker | V48: % change | W48: Rank
A49: 44537 | B49: 49.24 | C49: 49.88 | D49: 49.23 | E49: 49.77 | F49: 635800 | U49: ROG | V49: =IF($I$11="OK",INDEX('Peer Data'!$O$5:$O$1258,$I$10),"") -> 0.11884368 | W49: =IF($I$11="OK",RANK(V49,$V$49:$V$60),"") -> 7
A50: 44538 | B50: 50.67 | C50: 50.83 | D50: 50.32 | E50: 50.68 | F50: 542900 | U50: NVS | V50: =IF($I$11="OK",INDEX('Peer Data'!$P$5:$P$1258,$I$10),"") -> 0.78110588 | W50: =IF($I$11="OK",RANK(V50,$V$49:$V$60),"") -> 3
A51: 44539 | B51: 50.45 | C51: 50.68 | D51: 50.41 | E51: 50.47 | F51: 304400 | U51: AZN | V51: =IF($I$11="OK",INDEX('Peer Data'!$Q$5:$Q$1258,$I$10),"") -> 0.29669421 | W51: =IF($I$11="OK",RANK(V51,$V$49:$V$60),"") -> 6
A52: 44540 | B52: 51.09 | C52: 51.26 | D52: 50.97 | E52: 51.12 | F52: 482800 | U52: GSK | V52: =IF($I$11="OK",INDEX('Peer Data'!$R$5:$R$1258,$I$10),"") -> -0.01559393 | W52: =IF($I$11="OK",RANK(V52,$V$49:$V$60),"") -> 9
A53: 44543 | B53: 50.99 | C53: 51.19 | D53: 50.64 | E53: 50.64 | F53: 503200 | U53: SNY | V53: =IF($I$11="OK",INDEX('Peer Data'!$S$5:$S$1258,$I$10),"") -> -0.17384106 | W53: =IF($I$11="OK",RANK(V53,$V$49:$V$60),"") -> 11
A54: 44544 | B54: 50.07 | C54: 50.28 | D54: 49.28 | E54: 49.37 | F54: 803800 | U54: BAYNr | V54: =IF($I$11="OK",INDEX('Peer Data'!$T$5:$T$1258,$I$10),"") -> -0.026535254 | W54: =IF($I$11="OK",RANK(V54,$V$49:$V$60),"") -> 10
A55: 44545 | B55: 49.86 | C55: 50.68 | D55: 49.74 | E55: 50.62 | F55: 830000 | U55: MRK | V55: =IF($I$11="OK",INDEX('Peer Data'!$U$5:$U$1258,$I$10),"") -> 0.76838235 | W55: =IF($I$11="OK",RANK(V55,$V$49:$V$60),"") -> 4
...

Sheet Multiples
C1: Data | D1: Source | E1: Data | F1: Source | H1: Data | I1: Data source | J1: Data | K1: Data source | N1: Data | O1: Data source | P1: Data | Q1: Data source
C2: Market Cap ($bn, USD) | E2: Net Debt ($bn, USD) | G2: EV ($bn, USD) | H2: EPS (Forward FY2026) | J2: EPS (Forward FY2027) | L2: P/E (Forward 2026) | M2: P/E (Forward 2027) | N2: EBITDA (Forward FY2026) | P2: EBITDA (Forward FY2027) | R2: EV/EBITDA (Forward 2026) | S2: EV/EBITDA (Forward 2027)
B3: ABBV | C3: =F19*H19 -> 467.2258 | D3: Yahoo Finance market cap (ABBV), 2026-10-05 | E3: =(J19-K19)*I19 -> 64.315999 | F3: Yahoo Finance total debt less total cash, as of 2026-06-30 | G3: =C3+E3 -> 531.5418 | H3: 14.00737 | I3: Yahoo Finance consensus, 26 analysts, 2026-10-05; USD per share | J3: 16.25892 | K3: Yahoo Finance consensus, 25 analysts, 2026-10-05; USD per share | L3: =IF(H3>0,E19/H3,"n/m") -> 18.875778 | M3: =IF(J3>0,E19/J3,"n/m") -> 16.261843 | N3: =M19*L19*I19 -> 32.298386 | O3: Estimate: Yahoo consensus revenue FY2026E x TTM EBITDA margin | P3: =N19*L19*I19 -> 35.115423 | Q3: Estimate: Yahoo consensus revenue FY2027E x TTM EBITDA margin | R3: =IF(N3>0,G3/N3,"n/m") -> 16.457225 | S3: =IF(P3>0,G3/P3,"n/m") -> 15.13699
B4: AZN | C4: =F20*H20 -> 242.57718 | D4: Yahoo Finance market cap (AZN), 2026-10-05 | E4: =(J20-K20)*I20 -> 27.381999 | F4: Yahoo Finance total debt less total cash, as of 2026-06-30 | G4: =C4+E4 -> 269.95918 | H4: 10.07 | I4: Yahoo Finance consensus, 2 analysts, 2026-10-05; USD per share (NYSE ordinary share) | J4: 11.565 | K4: Yahoo Finance consensus, 2 analysts, 2026-10-05; USD per share (NYSE ordinary share) | L4: =IF(H4>0,E20/H4,"n/m") -> 15.532274 | M4: =IF(J4>0,E20/J4,"n/m") -> 13.524427 | N4: =M20*L20*I20 -> 20.48836 | O4: Estimate: Yahoo consensus revenue FY2026E x TTM EBITDA margin | P4: =N20*L20*I20 -> 21.744534 | Q4: Estimate: Yahoo consensus revenue FY2027E x TTM EBITDA margin | R4: =IF(N4>0,G4/N4,"n/m") -> 13.176222 | S4: =IF(P4>0,G4/P4,"n/m") -> 12.415036
B5: BAYNr | C5: =F21*H21 -> 48.44758 | D5: Yahoo Finance market cap (BAYN.DE), 2026-10-05, converted EUR->USD | E5: =(J21-K21)*I21 -> 37.410907 | F5: Yahoo Finance total debt less total cash, as of 2026-06-30, converted EUR->USD | G5: =C5+E5 -> 85.858487 | H5: 4.52573 | I5: Yahoo Finance consensus, 15 analysts, 2026-10-05; EUR per share (Xetra) | J5: 4.82607 | K5: Yahoo Finance consensus, 15 analysts, 2026-10-05; EUR per share (Xetra) | L5: =IF(H5>0,E21/H5,"n/m") -> 9.7133501 | M5: =IF(J5>0,E21/J5,"n/m") -> 9.1088608 | N5: =M21*L21*I21 -> 11.47964 | O5: Estimate: Yahoo consensus revenue FY2026E x TTM EBITDA margin, EUR->USD | P5: =N21*L21*I21 -> 11.791 | Q5: Estimate: Yahoo consensus revenue FY2027E x TTM EBITDA margin, EUR->USD | R5: =IF(N5>0,G5/N5,"n/m") -> 7.4791969 | S5: =IF(P5>0,G5/P5,"n/m") -> 7.2816968
B6: BMY | C6: =F22*H22 -> 120.63252 | D6: Yahoo Finance market cap (BMY), 2026-10-05 | E6: =(J22-K22)*I22 -> 33.986002 | F6: Yahoo Finance total debt less total cash, as of 2026-06-30 | G6: =C6+E6 -> 154.61852 | H6: 6.94853 | I6: Yahoo Finance consensus, 27 analysts, 2026-10-05; USD per share | J6: 6.56484 | K6: Yahoo Finance consensus, 28 analysts, 2026-10-05; USD per share | L6: =IF(H6>0,E22/H6,"n/m") -> 8.4989199 | M6: =IF(J6>0,E22/J6,"n/m") -> 8.9956496 | N6: =M22*L22*I22 -> 19.182877 | O6: Estimate: Yahoo consensus revenue FY2026E x TTM EBITDA margin | P6: =N22*L22*I22 -> 18.553817 | Q6: Estimate: Yahoo consensus revenue FY2027E x TTM EBITDA margin | R6: =IF(N6>0,G6/N6,"n/m") -> 8.0602363 | S6: =IF(P6>0,G6/P6,"n/m") -> 8.3335152
B7: GSK | C7: =F23*H23 -> 93.494043 | D7: Yahoo Finance market cap (GSK), 2026-10-05 | E7: =(J23-K23)*I23 -> 20.075696 | F7: Yahoo Finance total debt less total cash, as of 2026-06-30, converted GBP->USD | G7: =C7+E7 -> 113.56974 | H7: 4.75952 | I7: Yahoo Finance consensus, 5 analysts, 2026-10-05; USD per ADS | J7: 4.94036 | K7: Yahoo Finance consensus, 5 analysts, 2026-10-05; USD per ADS | L7: =IF(H7>0,E23/H7,"n/m") -> 9.8045601 | M7: =IF(J7>0,E23/J7,"n/m") -> 9.4456679 | N7: =M23*L23*I23 -> 14.605905 | O7: Estimate: Yahoo consensus revenue FY2026E x TTM EBITDA margin, GBP->USD | P7: =N23*L23*I23 -> 15.283174 | Q7: Estimate: Yahoo consensus revenue FY2027E x TTM EBITDA margin, GBP->USD | R7: =IF(N7>0,G7/N7,"n/m") -> 7.7756043 | S7: =IF(P7>0,G7/P7,"n/m") -> 7.4310308
B8: JnJ | C8: =F24*H24 -> 610.81289 | D8: Yahoo Finance market cap (JNJ), 2026-10-05 | E8: =(J24-K24)*I24 -> 28.278002 | F8: Yahoo Finance total debt less total cash, as of 2026-06-28 | G8: =C8+E8 -> 639.09089 | H8: 11.07747 | I8: Yahoo Finance consensus, 9 analysts, 2026-10-05; USD per share | J8: 12.10167 | K8: Yahoo Finance consensus, 8 analysts, 2026-10-05; USD per share | L8: =IF(H8>0,E24/H8,"n/m") -> 22.880676 | M8: =IF(J8>0,E24/J8,"n/m") -> 20.944217 | N8: =M24*L24*I24 -> 36.099258 | O8: Estimate: Yahoo consensus revenue FY2026E x TTM EBITDA margin | P8: =N24*L24*I24 -> 38.675035 | Q8: Estimate: Yahoo consensus revenue FY2027E x TTM EBITDA margin | R8: =IF(N8>0,G8/N8,"n/m") -> 17.703713 | S8: =IF(P8>0,G8/P8,"n/m") -> 16.524636
B9: LLY | C9: =F25*H25 -> 1024.1516 | D9: Yahoo Finance market cap (LLY), 2026-10-05 | E9: =(J25-K25)*I25 -> 45.957999 | F9: Yahoo Finance total debt less total cash, as of 2026-06-30 | G9: =C9+E9 -> 1070.1096 | H9: 36.94997 | I9: Yahoo Finance consensus, 27 analysts, 2026-10-05; USD per share | J9: 47.59245 | K9: Yahoo Finance consensus, 27 analysts, 2026-10-05; USD per share | L9: =IF(H9>0,E25/H9,"n/m") -> 31.082163 | M9: =IF(J9>0,E25/J9,"n/m") -> 24.131664 | N9: =M25*L25*I25 -> 46.328919 | O9: Estimate: Yahoo consensus revenue FY2026E x TTM EBITDA margin | P9: =N25*L25*I25 -> 53.477154 | Q9: Estimate: Yahoo consensus revenue FY2027E x TTM EBITDA margin | R9: =IF(N9>0,G9/N9,"n/m") -> 23.098091 | S9: =IF(P9>0,G9/P9,"n/m") -> 20.010593
B10: MRK | C10: =F26*H26 -> 344.95994 | D10: Yahoo Finance market cap (MRK), 2026-10-05 | E10: =(J26-K26)*I26 -> 46.769999 | F10: Yahoo Finance total debt less total cash, as of 2026-06-30 | G10: =C10+E10 -> 391.72994 | H10: 2.72846 | I10: Yahoo Finance consensus, 25 analysts, 2026-10-05; USD per share | J10: 9.46926 | K10: Yahoo Finance consensus, 24 analysts, 2026-10-05; USD per share | L10: =IF(H10>0,E26/H10,"n/m") -> 51.245025 | M10: =IF(J10>0,E26/J10,"n/m") -> 14.765673 | N10: =M26*L26*I26 -> 29.113958 | O10: Estimate: Yahoo consensus revenue FY2026E x TTM EBITDA margin | P10: =N26*L26*I26 -> 30.439027 | Q10: Estimate: Yahoo consensus revenue FY2027E x TTM EBITDA margin | R10: =IF(N10>0,G10/N10,"n/m") -> 13.455056 | S10: =IF(P10>0,G10/P10,"n/m") -> 12.869332
B11: NVS | C11: =F27*H27 -> 267.20249 | D11: Yahoo Finance market cap (NVS), 2026-10-05 | E11: =(J27-K27)*I27 -> 41.396002 | F11: Yahoo Finance total debt less total cash, as of 2026-06-30 | G11: =C11+E11 -> 308.5985 | H11: 8.87485 | I11: Yahoo Finance consensus, 9 analysts, 2026-10-05; USD per ADS | J11: 9.84148 | K11: Yahoo Finance consensus, 10 analysts, 2026-10-05; USD per ADS | L11: =IF(H11>0,E27/H11,"n/m") -> 15.840268 | M11: =IF(J11>0,E27/J11,"n/m") -> 14.284437 | N11: =M27*L27*I27 -> 23.50701 | O11: Estimate: Yahoo consensus revenue FY2026E x TTM EBITDA margin | P11: =N27*L27*I27 -> 25.023313 | Q11: Estimate: Yahoo consensus revenue FY2027E x TTM EBITDA margin | R11: =IF(N11>0,G11/N11,"n/m") -> 13.127935 | S11: =IF(P11>0,G11/P11,"n/m") -> 12.33244
B12: PFE | C12: =F28*H28 -> 156.62532 | D12: Yahoo Finance market cap (PFE), 2026-10-05 | E12: =(J28-K28)*I28 -> 51.776 | F12: Yahoo Finance total debt less total cash, as of 2026-06-28 | G12: =C12+E12 -> 208.40132 | H12: 2.97497 | I12: Yahoo Finance consensus, 25 analysts, 2026-10-05; USD per share | J12: 2.89684 | K12: Yahoo Finance consensus, 25 analysts, 2026-10-05; USD per share | L12: =IF(H12>0,E28/H12,"n/m") -> 9.2369671 | M12: =IF(J12>0,E28/J12,"n/m") -> 9.4860952 | N12: =M28*L28*I28 -> 24.80077 | O12: Estimate: Yahoo consensus revenue FY2026E x TTM EBITDA margin | P12: =N28*L28*I28 -> 23.861535 | Q12: Estimate: Yahoo consensus revenue FY2027E x TTM EBITDA margin | R12: =IF(N12>0,G12/N12,"n/m") -> 8.4030181 | S12: =IF(P12>0,G12/P12,"n/m") -> 8.733777
B13: ROG | C13: =F29*H29 -> 335.02413 | D13: Yahoo Finance market cap (RHHBY), 2026-10-05 | E13: =(J29-K29)*I29 -> 28.373667 | F13: Yahoo Finance total debt less total cash, as of 2026-06-30, converted CHF->USD | G13: =C13+E13 -> 363.3978 | H13: 3.13226 | I13: Yahoo Finance consensus, 5 analysts, 2026-10-05; USD per ADR (RHHBY, OTC) | J13: 3.3734 | K13: Yahoo Finance consensus, 5 analysts, 2026-10-05; USD per ADR (RHHBY, OTC) | L13: =IF(H13>0,E29/H13,"n/m") -> 16.780216 | M13: =IF(J13>0,E29/J13,"n/m") -> 15.58072 | N13: =M29*L29*I29 -> 28.719991 | O13: Estimate: Yahoo consensus revenue FY2026E x TTM EBITDA margin, CHF->USD | P13: =N29*L29*I29 -> 30.026667 | Q13: Estimate: Yahoo consensus revenue FY2027E x TTM EBITDA margin, CHF->USD | R13: =IF(N13>0,G13/N13,"n/m") -> 12.65313 | S13: =IF(P13>0,G13/P13,"n/m") -> 12.102502
B14: SNY | C14: =F30*H30 -> 94.803173 | D14: Yahoo Finance market cap (SNY), 2026-10-05 | E14: =(J30-K30)*I30 -> 19.324127 | F14: Yahoo Finance total debt less total cash, as of 2026-06-30, converted EUR->USD | G14: =C14+E14 -> 114.1273 | H14: 5.01613 | I14: Yahoo Finance consensus, 6 analysts, 2026-10-05; USD per ADS | J14: 5.40092 | K14: Yahoo Finance consensus, 6 analysts, 2026-10-05; USD per ADS | L14: =IF(H14>0,E30/H14,"n/m") -> 7.8875547 | M14: =IF(J14>0,E30/J14,"n/m") -> 7.3256038 | N14: =M30*L30*I30 -> 14.802539 | O14: Estimate: Yahoo consensus revenue FY2026E x TTM EBITDA margin, EUR->USD | P14: =N30*L30*I30 -> 15.721947 | Q14: Estimate: Yahoo consensus revenue FY2027E x TTM EBITDA margin, EUR->USD | R14: =IF(N14>0,G14/N14,"n/m") -> 7.7099815 | S14: =IF(P14>0,G14/P14,"n/m") -> 7.2591071
B15: Average | L15: =AVERAGE(L3:L14) -> 18.114813 | M15: =AVERAGE(M3:M14) -> 13.654571 | R15: =AVERAGE(R3:R14) -> 12.424951 | S15: =AVERAGE(S3:S14) -> 11.702555
B17: Supporting inputs - Yahoo Finance snapshot retrieved 2026-10-05 (blue = hardcoded input). Amounts in billions of the stated currency.
B18: Ticker | C18: Yahoo symbol | D18: Quote ccy | E18: Price (quote ccy) | F18: Market cap (quote ccy, bn) | G18: Financial ccy | H18: FX quote->USD | I18: FX financial->USD | J18: Total debt (fin ccy, bn) | K18: Total cash (fin ccy, bn) | L18: TTM EBITDA margin | M18: Revenue FY2026E (fin ccy, bn) | N18: Revenue FY2027E (fin ccy, bn) | O18: # analysts EPS FY26 | P18: # analysts EPS FY27 | Q18: Balance sheet date
B19: ABBV | C19: ABBV | D19: USD | E19: 264.4 | F19: 467.2258 | G19: USD | H19: =INDEX($C$35:$C$38,MATCH(D19,$B$35:$B$38,0)) -> 1 | I19: =INDEX($C$35:$C$38,MATCH(G19,$B$35:$B$38,0)) -> 1 | J19: 70.884999 | K19: 6.5689999 | L19: 0.47779 | M19: 67.599543 | N19: 73.495516 | O19: 26 | P19: 25 | Q19: 46203
B20: AZN | C20: AZN | D20: USD | E20: 156.41 | F20: 242.57718 | G20: USD | H20: =INDEX($C$35:$C$38,MATCH(D20,$B$35:$B$38,0)) -> 1 | I20: =INDEX($C$35:$C$38,MATCH(G20,$B$35:$B$38,0)) -> 1 | J20: 32.349999 | K20: 4.968 | L20: 0.32435 | M20: 63.167443 | N20: 67.040339 | O20: 2 | P20: 2 | Q20: 46203
B21: BAYNr | C21: BAYN.DE | D21: EUR | E21: 43.96 | F21: 43.18736 | G21: EUR | H21: =INDEX($C$35:$C$38,MATCH(D21,$B$35:$B$38,0)) -> 1.1218 | I21: =INDEX($C$35:$C$38,MATCH(G21,$B$35:$B$38,0)) -> 1.1218 | J21: 38.430999 | K21: 5.0819999 | L21: 0.22332 | M21: 45.823178 | N21: 47.066032 | O21: 15 | P21: 15 | Q21: 46203
B22: BMY | C22: BMY | D22: USD | E22: 59.055 | F22: 120.63252 | G22: USD | H22: =INDEX($C$35:$C$38,MATCH(D22,$B$35:$B$38,0)) -> 1 | I22: =INDEX($C$35:$C$38,MATCH(G22,$B$35:$B$38,0)) -> 1 | J22: 45.053002 | K22: 11.067 | L22: 0.38487 | M22: 49.842483 | N22: 48.208012 | O22: 27 | P22: 28 | Q22: 46203
B23: GSK | C23: GSK | D23: USD | E23: 46.665 | F23: 93.494043 | G23: GBP | H23: =INDEX($C$35:$C$38,MATCH(D23,$B$35:$B$38,0)) -> 1 | I23: =INDEX($C$35:$C$38,MATCH(G23,$B$35:$B$38,0)) -> 1.3219 | J23: 18.293 | K23: 3.1059999 | L23: 0.32581002 | M23: 33.912939 | N23: 35.485467 | O23: 5 | P23: 5 | Q23: 46203
B24: JnJ | C24: JNJ | D24: USD | E24: 253.46 | F24: 610.81289 | G24: USD | H24: =INDEX($C$35:$C$38,MATCH(D24,$B$35:$B$38,0)) -> 1 | I24: =INDEX($C$35:$C$38,MATCH(G24,$B$35:$B$38,0)) -> 1 | J24: 49.036001 | K24: 20.758 | L24: 0.35609 | M24: 101.37678 | N24: 108.61028 | O24: 9 | P24: 8 | Q24: 46201
B25: LLY | C25: LLY | D25: USD | E25: 1148.485 | F25: 1024.1516 | G25: USD | H25: =INDEX($C$35:$C$38,MATCH(D25,$B$35:$B$38,0)) -> 1 | I25: =INDEX($C$35:$C$38,MATCH(G25,$B$35:$B$38,0)) -> 1 | J25: 54.907998 | K25: 8.9499996 | L25: 0.52352 | M25: 88.495031 | N25: 102.14921 | O25: 27 | P25: 27 | Q25: 46203
B26: MRK | C26: MRK | D26: USD | E26: 139.82 | F26: 344.95994 | G26: USD | H26: =INDEX($C$35:$C$38,MATCH(D26,$B$35:$B$38,0)) -> 1 | I26: =INDEX($C$35:$C$38,MATCH(G26,$B$35:$B$38,0)) -> 1 | J26: 53.910999 | K26: 7.1410002 | L26: 0.4337 | M26: 67.129256 | N26: 70.184521 | O26: 25 | P26: 24 | Q26: 46203
B27: NVS | C27: NVS | D27: USD | E27: 140.58 | F27: 267.20249 | G27: USD | H27: =INDEX($C$35:$C$38,MATCH(D27,$B$35:$B$38,0)) -> 1 | I27: =INDEX($C$35:$C$38,MATCH(G27,$B$35:$B$38,0)) -> 1 | J27: 49.014002 | K27: 7.6179999 | L27: 0.40742 | M27: 57.69724 | N27: 61.41896 | O27: 9 | P27: 10 | Q27: 46203
B28: PFE | C28: PFE | D28: USD | E28: 27.4797 | F28: 156.62532 | G28: USD | H28: =INDEX($C$35:$C$38,MATCH(D28,$B$35:$B$38,0)) -> 1 | I28: =INDEX($C$35:$C$38,MATCH(G28,$B$35:$B$38,0)) -> 1 | J28: 63.480001 | K28: 11.704001 | L28: 0.3985 | M28: 62.235308 | N28: 59.87838 | O28: 25 | P28: 25 | Q28: 46201
B29: ROG | C29: RHHBY | D29: USD | E29: 52.56 | F29: 335.02413 | G29: CHF | H29: =INDEX($C$35:$C$38,MATCH(D29,$B$35:$B$38,0)) -> 1 | I29: =INDEX($C$35:$C$38,MATCH(G29,$B$35:$B$38,0)) -> 1.2036 | J29: 33.308 | K29: 9.7339996 | L29: 0.38063 | M29: 62.690121 | N29: 65.54234 | O29: 5 | P29: 5 | Q29: 46203
B30: SNY | C30: SNY | D30: USD | E30: 39.565 | F30: 94.803173 | G30: EUR | H30: =INDEX($C$35:$C$38,MATCH(D30,$B$35:$B$38,0)) -> 1 | I30: =INDEX($C$35:$C$38,MATCH(G30,$B$35:$B$38,0)) -> 1.1218 | J30: 23.576001 | K30: 6.3500001 | L30: 0.27685 | M30: 47.662437 | N30: 50.622825 | O30: 6 | P30: 6 | Q30: 46203
B33: FX rates to USD (Yahoo Finance, 2026-10-05)
B34: Currency | C34: USD per unit
B35: USD | C35: 1
B36: EUR | C36: 1.1218
B37: GBP | C37: 1.3219
B38: CHF | C38: 1.2036
B40: Notes
B41: 1. EV = Market cap + Net debt. Net debt = total debt (incl. leases, per Yahoo) - total cash & short-term investments, latest reported quarter.
B42: 2. P/E = Yahoo snapshot price / consensus EPS, both in the listing's quote currency (BAYNr in EUR; all others USD per share/ADS/ADR). 'n/m' if EPS <= 0.
B43: 3. Forward EBITDA is NOT a consensus figure: no free source publishes EBITDA estimates, so it is estimated as consensus revenue x trailing-12-month EBITDA margin. Margins include one-off items (e.g. MRK's H1 2026 charges), so treat EV/EBITDA as indicative.
B44: 4. Consensus EPS is as published by Yahoo Finance and may be on an adjusted (non-GAAP / core) basis. Nasdaq consensus is within ~2% for most names; AZN differs more (Yahoo has only 2 analysts).
...

Sheet Peer Data
A1: Peer Comps - Daily Close and % Change vs Start Date
A2: Closes copied from models/<TICKER>.xlsx (Stock Price tab) on 2026-10-05 and aligned to ROG trading days (last close on or before each date). Each stock's % change is in its own currency (BAYNr in EUR, others USD). % columns follow Start/End Date in 'Stock Price'!I4:I5.
AB3: Chart label helper (spaces out end-of-line labels; do not edit)
A4: Date | B4: ROG Close | C4: NVS Close | D4: AZN Close | E4: GSK Close | F4: SNY Close | G4: BAYNr Close | H4: MRK Close | I4: PFE Close | J4: LLY Close | K4: BMY Close | L4: JnJ Close | M4: ABBV Close | O4: ROG % chg | P4: NVS % chg | Q4: AZN % chg | R4: GSK % chg | S4: SNY % chg | T4: BAYNr % chg | U4: MRK % chg | V4: PFE % chg | W4: LLY % chg | X4: BMY % chg | Y4: JnJ % chg | Z4: ABBV % chg | AB4: Ticker | AC4: % change | AD4: Sort key | AE4: Order | AF4: Label | AG4: Label Y | AH4: # | AI4: Sorted key | AJ4: Push down | AK4: Push up (final) | AL4: Min gap | AM4: Data min
A5: ='Stock Price'!A5 -> 44474 | B5: ='Stock Price'!E5 -> 46.7 | C5: 79.1643 | D5: 121 | E5: 47.775 | F5: 48.32 | G5: 46.165 | H5: 81.6 | I5: 42.32 | J5: 230.93 | K5: 59.15 | L5: 159.58 | M5: 109.51 | O5: =IF('Stock Price'!$I$11="OK",B5/INDEX(B$5:B$1258,'Stock Price'!$I$9)-1,"") -> 0 | P5: =IF('Stock Price'!$I$11="OK",C5/INDEX(C$5:C$1258,'Stock Price'!$I$9)-1,"") -> 0 | Q5: =IF('Stock Price'!$I$11="OK",D5/INDEX(D$5:D$1258,'Stock Price'!$I$9)-1,"") -> 0 | R5: =IF('Stock Price'!$I$11="OK",E5/INDEX(E$5:E$1258,'Stock Price'!$I$9)-1,"") -> 0 | S5: =IF('Stock Price'!$I$11="OK",F5/INDEX(F$5:F$1258,'Stock Price'!$I$9)-1,"") -> 0 | T5: =IF('Stock Price'!$I$11="OK",G5/INDEX(G$5:G$1258,'Stock Price'!$I$9)-1,"") -> 0 | U5: =IF('Stock Price'!$I$11="OK",H5/INDEX(H$5:H$1258,'Stock Price'!$I$9)-1,"") -> 0 | V5: =IF('Stock Price'!$I$11="OK",I5/INDEX(I$5:I$1258,'Stock Price'!$I$9)-1,"") -> 0 | ... Z5: =IF('Stock Price'!$I$11="OK",M5/INDEX(M$5:M$1258,'Stock Price'!$I$9)-1,"") -> 0 | AB5: ROG | AC5: ='Stock Price'!V49 -> 0.11884368 | AD5: =IF(AC5="","",AC5-ROW()*0.000000001) -> 0.11884368 | AE5: =IF(AD5="","",COUNTIF($AD$5:$AD$16,">"&AD5)+1) -> 7 | AF5: =IF(AC5="",AB5,AB5&" "&TEXT(AC5,"+0.0%;-0.0%;0.0%")) -> ROG +11.9% | AG5: =IF(AE5="","",INDEX($AK$5:$AK$16,AE5)) -> 0.56424463 | AH5: 1 | AI5: =IF('Stock Price'!$I$11="OK",LARGE($AD$5:$AD$16,AH5),"") -> 3.9489023 | AJ5: =AI5 -> 3.9489023 | AK5: =IF('Stock Price'!$I$11="OK",MAX(AJ5,AK6+$AL$5),"") -> 3.9489023 | AL5: =IF('Stock Price'!$I$11="OK",0.045*(MAX(INDEX('Peer Data'!$O$5:$Z$1258,'Stock Price'!$I$9,1):INDEX('Peer Data'!$O$5:$Z$1258,'Stock Price'!$I$10,12))-MIN(INDEX('Peer Data'!$O$5:$Z$1258,'Stock Price'!$I$9,1):INDEX('Peer Data'!$O$5:$Z$1258,'Stock Price'!$I$10,12))),"") -> 0.23109868 | AM5: =IF('Stock Price'!$I$11="OK",MIN(INDEX('Peer Data'!$O$5:$Z$1258,'Stock Price'!$I$9,1):INDEX('Peer Data'!$O$5:$Z$1258,'Stock Price'!$I$10,12)),"") -> -0.59124878
A6: ='Stock Price'!A6 -> 44475 | B6: ='Stock Price'!E6 -> 47.23 | C6: 79.1256 | D6: 120.27 | E6: 47.6625 | F6: 48.2 | G6: 46.335 | H6: 80.66 | I6: 42.02 | J6: 227.85 | K6: 59.19 | L6: 159.91 | M6: 109.32 | O6: =IF('Stock Price'!$I$11="OK",B6/INDEX(B$5:B$1258,'Stock Price'!$I$9)-1,"") -> 0.011349036 | P6: =IF('Stock Price'!$I$11="OK",C6/INDEX(C$5:C$1258,'Stock Price'!$I$9)-1,"") -> -0.00048885672 | Q6: =IF('Stock Price'!$I$11="OK",D6/INDEX(D$5:D$1258,'Stock Price'!$I$9)-1,"") -> -0.0060330579 | R6: =IF('Stock Price'!$I$11="OK",E6/INDEX(E$5:E$1258,'Stock Price'!$I$9)-1,"") -> -0.0023547881 | S6: =IF('Stock Price'!$I$11="OK",F6/INDEX(F$5:F$1258,'Stock Price'!$I$9)-1,"") -> -0.0024834437 | T6: =IF('Stock Price'!$I$11="OK",G6/INDEX(G$5:G$1258,'Stock Price'!$I$9)-1,"") -> 0.0036824434 | U6: =IF('Stock Price'!$I$11="OK",H6/INDEX(H$5:H$1258,'Stock Price'!$I$9)-1,"") -> -0.011519608 | V6: =IF('Stock Price'!$I$11="OK",I6/INDEX(I$5:I$1258,'Stock Price'!$I$9)-1,"") -> -0.0070888469 | ... Z6: =IF('Stock Price'!$I$11="OK",M6/INDEX(M$5:M$1258,'Stock Price'!$I$9)-1,"") -> -0.0017350014 | AB6: NVS | AC6: ='Stock Price'!V50 -> 0.78110588 | AD6: =IF(AC6="","",AC6-ROW()*0.000000001) -> 0.78110587 | AE6: =IF(AD6="","",COUNTIF($AD$5:$AD$16,">"&AD6)+1) -> 3 | AF6: =IF(AC6="",AB6,AB6&" "&TEXT(AC6,"+0.0%;-0.0%;0.0%")) -> NVS +78.1% | AG6: =IF(AE6="","",INDEX($AK$5:$AK$16,AE6)) -> 1.4886394 | AH6: 2 | AI6: =IF('Stock Price'!$I$11="OK",LARGE($AD$5:$AD$16,AH6),"") -> 1.3999635 | AJ6: =IF('Stock Price'!$I$11="OK",MIN(AI6,AJ5-$AL$5),"") -> 1.3999635 | AK6: =IF('Stock Price'!$I$11="OK",MAX(AJ6,AK7+$AL$5),"") -> 1.719738
A7: ='Stock Price'!A7 -> 44476 | B7: ='Stock Price'!E7 -> 48.05 | C7: 79.7931 | D7: 121.98 | E7: 48.325 | F7: 48.6 | G7: 47.36 | H7: 81.94 | I7: 42.74 | J7: 233.18 | K7: 59.01 | L7: 161.34 | M7: 110.87 | O7: =IF('Stock Price'!$I$11="OK",B7/INDEX(B$5:B$1258,'Stock Price'!$I$9)-1,"") -> 0.028907923 | P7: =IF('Stock Price'!$I$11="OK",C7/INDEX(C$5:C$1258,'Stock Price'!$I$9)-1,"") -> 0.0079429743 | Q7: =IF('Stock Price'!$I$11="OK",D7/INDEX(D$5:D$1258,'Stock Price'!$I$9)-1,"") -> 0.0080991736 | R7: =IF('Stock Price'!$I$11="OK",E7/INDEX(E$5:E$1258,'Stock Price'!$I$9)-1,"") -> 0.011512297 | S7: =IF('Stock Price'!$I$11="OK",F7/INDEX(F$5:F$1258,'Stock Price'!$I$9)-1,"") -> 0.005794702 | T7: =IF('Stock Price'!$I$11="OK",G7/INDEX(G$5:G$1258,'Stock Price'!$I$9)-1,"") -> 0.025885411 | U7: =IF('Stock Price'!$I$11="OK",H7/INDEX(H$5:H$1258,'Stock Price'!$I$9)-1,"") -> 0.0041666667 | V7: =IF('Stock Price'!$I$11="OK",I7/INDEX(I$5:I$1258,'Stock Price'!$I$9)-1,"") -> 0.0099243856 | ... Z7: =IF('Stock Price'!$I$11="OK",M7/INDEX(M$5:M$1258,'Stock Price'!$I$9)-1,"") -> 0.012418957 | AB7: AZN | AC7: ='Stock Price'!V51 -> 0.29669421 | AD7: =IF(AC7="","",AC7-ROW()*0.000000001) -> 0.29669421 | AE7: =IF(AD7="","",COUNTIF($AD$5:$AD$16,">"&AD7)+1) -> 6 | AF7: =IF(AC7="",AB7,AB7&" "&TEXT(AC7,"+0.0%;-0.0%;0.0%")) -> AZN +29.7% | AG7: =IF(AE7="","",INDEX($AK$5:$AK$16,AE7)) -> 0.79534331 | AH7: 3 | AI7: =IF('Stock Price'!$I$11="OK",LARGE($AD$5:$AD$16,AH7),"") -> 0.78110587 | AJ7: =IF('Stock Price'!$I$11="OK",MIN(AI7,AJ6-$AL$5),"") -> 0.78110587 | AK7: =IF('Stock Price'!$I$11="OK",MAX(AJ7,AK8+$AL$5),"") -> 1.4886394
A8: ='Stock Price'!A8 -> 44477 | B8: ='Stock Price'!E8 -> 49.89 | C8: 80.1317 | D8: 123.83 | E8: 48.3875 | F8: 49.01 | G8: 47.75 | H8: 80.63 | I8: 42.45 | J8: 233.94 | K8: 57.26 | L8: 160.93 | M8: 111.18 | O8: =IF('Stock Price'!$I$11="OK",B8/INDEX(B$5:B$1258,'Stock Price'!$I$9)-1,"") -> 0.068308351 | P8: =IF('Stock Price'!$I$11="OK",C8/INDEX(C$5:C$1258,'Stock Price'!$I$9)-1,"") -> 0.012220155 | Q8: =IF('Stock Price'!$I$11="OK",D8/INDEX(D$5:D$1258,'Stock Price'!$I$9)-1,"") -> 0.02338843 | R8: =IF('Stock Price'!$I$11="OK",E8/INDEX(E$5:E$1258,'Stock Price'!$I$9)-1,"") -> 0.012820513 | S8: =IF('Stock Price'!$I$11="OK",F8/INDEX(F$5:F$1258,'Stock Price'!$I$9)-1,"") -> 0.014279801 | T8: =IF('Stock Price'!$I$11="OK",G8/INDEX(G$5:G$1258,'Stock Price'!$I$9)-1,"") -> 0.034333369 | U8: =IF('Stock Price'!$I$11="OK",H8/INDEX(H$5:H$1258,'Stock Price'!$I$9)-1,"") -> -0.011887255 | V8: =IF('Stock Price'!$I$11="OK",I8/INDEX(I$5:I$1258,'Stock Price'!$I$9)-1,"") -> 0.0030718336 | ... Z8: =IF('Stock Price'!$I$11="OK",M8/INDEX(M$5:M$1258,'Stock Price'!$I$9)-1,"") -> 0.015249749 | AB8: GSK | AC8: ='Stock Price'!V52 -> -0.01559393 | AD8: =IF(AC8="","",AC8-ROW()*0.000000001) -> -0.015593938 | AE8: =IF(AD8="","",COUNTIF($AD$5:$AD$16,">"&AD8)+1) -> 9 | AF8: =IF(AC8="",AB8,AB8&" "&TEXT(AC8,"+0.0%;-0.0%;0.0%")) -> GSK -1.6% | AG8: =IF(AE8="","",INDEX($AK$5:$AK$16,AE8)) -> 0.10204726 | AH8: 4 | AI8: =IF('Stock Price'!$I$11="OK",LARGE($AD$5:$AD$16,AH8),"") -> 0.76838234 | AJ8: =IF('Stock Price'!$I$11="OK",MIN(AI8,AJ7-$AL$5),"") -> 0.55000719 | AK8: =IF('Stock Price'!$I$11="OK",MAX(AJ8,AK9+$AL$5),"") -> 1.2575407
A9: ='Stock Price'!A9 -> 44480 | B9: ='Stock Price'!E9 -> 48.83 | C9: 79.6577 | D9: 123.4924 | E9: 47.8 | F9: 48.68 | G9: 48.615 | H9: 79.93 | I9: 42.06 | J9: 233.67 | K9: 57.42 | L9: 160.25 | M9: 110.34 | O9: =IF('Stock Price'!$I$11="OK",B9/INDEX(B$5:B$1258,'Stock Price'!$I$9)-1,"") -> 0.045610278 | P9: =IF('Stock Price'!$I$11="OK",C9/INDEX(C$5:C$1258,'Stock Price'!$I$9)-1,"") -> 0.0062326074 | Q9: =IF('Stock Price'!$I$11="OK",D9/INDEX(D$5:D$1258,'Stock Price'!$I$9)-1,"") -> 0.020598347 | R9: =IF('Stock Price'!$I$11="OK",E9/INDEX(E$5:E$1258,'Stock Price'!$I$9)-1,"") -> 0.00052328624 | S9: =IF('Stock Price'!$I$11="OK",F9/INDEX(F$5:F$1258,'Stock Price'!$I$9)-1,"") -> 0.0074503311 | T9: =IF('Stock Price'!$I$11="OK",G9/INDEX(G$5:G$1258,'Stock Price'!$I$9)-1,"") -> 0.053070508 | U9: =IF('Stock Price'!$I$11="OK",H9/INDEX(H$5:H$1258,'Stock Price'!$I$9)-1,"") -> -0.020465686 | V9: =IF('Stock Price'!$I$11="OK",I9/INDEX(I$5:I$1258,'Stock Price'!$I$9)-1,"") -> -0.0061436673 | ... Z9: =IF('Stock Price'!$I$11="OK",M9/INDEX(M$5:M$1258,'Stock Price'!$I$9)-1,"") -> 0.0075792165 | AB9: SNY | AC9: ='Stock Price'!V53 -> -0.17384106 | AD9: =IF(AC9="","",AC9-ROW()*0.000000001) -> -0.17384107 | AE9: =IF(AD9="","",COUNTIF($AD$5:$AD$16,">"&AD9)+1) -> 11 | AF9: =IF(AC9="",AB9,AB9&" "&TEXT(AC9,"+0.0%;-0.0%;0.0%")) -> SNY -17.4% | AG9: =IF(AE9="","",INDEX($AK$5:$AK$16,AE9)) -> -0.3601501 | AH9: 5 | AI9: =IF('Stock Price'!$I$11="OK",LARGE($AD$5:$AD$16,AH9),"") -> 0.60439903 | AJ9: =IF('Stock Price'!$I$11="OK",MIN(AI9,AJ8-$AL$5),"") -> 0.31890851 | AK9: =IF('Stock Price'!$I$11="OK",MAX(AJ9,AK10+$AL$5),"") -> 1.026442
A10: ='Stock Price'!A10 -> 44481 | B10: ='Stock Price'!E10 -> 48.23 | C10: 79.3094 | D10: 122.92 | E10: 48.3 | F10: 48.3 | G10: 47.715 | H10: 79.59 | I10: 41.85 | J10: 232.78 | K10: 57.06 | L10: 157.69 | M10: 108.57 | O10: =IF('Stock Price'!$I$11="OK",B10/INDEX(B$5:B$1258,'Stock Price'!$I$9)-1,"") -> 0.032762313 | P10: =IF('Stock Price'!$I$11="OK",C10/INDEX(C$5:C$1258,'Stock Price'!$I$9)-1,"") -> 0.0018328969 | Q10: =IF('Stock Price'!$I$11="OK",D10/INDEX(D$5:D$1258,'Stock Price'!$I$9)-1,"") -> 0.015867769 | R10: =IF('Stock Price'!$I$11="OK",E10/INDEX(E$5:E$1258,'Stock Price'!$I$9)-1,"") -> 0.010989011 | S10: =IF('Stock Price'!$I$11="OK",F10/INDEX(F$5:F$1258,'Stock Price'!$I$9)-1,"") -> -0.00041390728 | T10: =IF('Stock Price'!$I$11="OK",G10/INDEX(G$5:G$1258,'Stock Price'!$I$9)-1,"") -> 0.033575219 | U10: =IF('Stock Price'!$I$11="OK",H10/INDEX(H$5:H$1258,'Stock Price'!$I$9)-1,"") -> -0.024632353 | V10: =IF('Stock Price'!$I$11="OK",I10/INDEX(I$5:I$1258,'Stock Price'!$I$9)-1,"") -> -0.01110586 | ... Z10: =IF('Stock Price'!$I$11="OK",M10/INDEX(M$5:M$1258,'Stock Price'!$I$9)-1,"") -> -0.008583691 | AB10: BAYNr | AC10: ='Stock Price'!V54 -> -0.026535254 | AD10: =IF(AC10="","",AC10-ROW()*0.000000001) -> -0.026535264 | AE10: =IF(AD10="","",COUNTIF($AD$5:$AD$16,">"&AD10)+1) -> 10 | AF10: =IF(AC10="",AB10,AB10&" "&TEXT(AC10,"+0.0%;-0.0%;0.0%")) -> BAYNr -2.7% | AG10: =IF(AE10="","",INDEX($AK$5:$AK$16,AE10)) -> -0.12905142 | AH10: 6 | AI10: =IF('Stock Price'!$I$11="OK",LARGE($AD$5:$AD$16,AH10),"") -> 0.29669421 | AJ10: =IF('Stock Price'!$I$11="OK",MIN(AI10,AJ9-$AL$5),"") -> 0.087809825 | AK10: =IF('Stock Price'!$I$11="OK",MAX(AJ10,AK11+$AL$5),"") -> 0.79534331
A11: ='Stock Price'!A11 -> 44482 | B11: ='Stock Price'!E11 -> 48.22 | C11: 79.7448 | D11: 119.09 | E11: 48.5 | F11: 48.22 | G11: 47.085 | H11: 78.95 | I11: 41.42 | J11: 236.44 | K11: 57.07 | L11: 159.2 | M11: 108.53 | O11: =IF('Stock Price'!$I$11="OK",B11/INDEX(B$5:B$1258,'Stock Price'!$I$9)-1,"") -> 0.03254818 | P11: =IF('Stock Price'!$I$11="OK",C11/INDEX(C$5:C$1258,'Stock Price'!$I$9)-1,"") -> 0.0073328508 | Q11: =IF('Stock Price'!$I$11="OK",D11/INDEX(D$5:D$1258,'Stock Price'!$I$9)-1,"") -> -0.015785124 | R11: =IF('Stock Price'!$I$11="OK",E11/INDEX(E$5:E$1258,'Stock Price'!$I$9)-1,"") -> 0.015175301 | S11: =IF('Stock Price'!$I$11="OK",F11/INDEX(F$5:F$1258,'Stock Price'!$I$9)-1,"") -> -0.0020695364 | T11: =IF('Stock Price'!$I$11="OK",G11/INDEX(G$5:G$1258,'Stock Price'!$I$9)-1,"") -> 0.019928517 | U11: =IF('Stock Price'!$I$11="OK",H11/INDEX(H$5:H$1258,'Stock Price'!$I$9)-1,"") -> -0.03247549 | V11: =IF('Stock Price'!$I$11="OK",I11/INDEX(I$5:I$1258,'Stock Price'!$I$9)-1,"") -> -0.021266541 | ... Z11: =IF('Stock Price'!$I$11="OK",M11/INDEX(M$5:M$1258,'Stock Price'!$I$9)-1,"") -> -0.0089489544 | AB11: MRK | AC11: ='Stock Price'!V55 -> 0.76838235 | AD11: =IF(AC11="","",AC11-ROW()*0.000000001) -> 0.76838234 | AE11: =IF(AD11="","",COUNTIF($AD$5:$AD$16,">"&AD11)+1) -> 4 | AF11: =IF(AC11="",AB11,AB11&" "&TEXT(AC11,"+0.0%;-0.0%;0.0%")) -> MRK +76.8% | AG11: =IF(AE11="","",INDEX($AK$5:$AK$16,AE11)) -> 1.2575407 | AH11: 7 | AI11: =IF('Stock Price'!$I$11="OK",LARGE($AD$5:$AD$16,AH11),"") -> 0.11884368 | AJ11: =IF('Stock Price'!$I$11="OK",MIN(AI11,AJ10-$AL$5),"") -> -0.14328886 | AK11: =IF('Stock Price'!$I$11="OK",MAX(AJ11,AK12+$AL$5),"") -> 0.56424463
A12: ='Stock Price'!A12 -> 44483 | B12: ='Stock Price'!E12 -> 48.25 | C12: 79.9092 | D12: 121 | E12: 48.4 | F12: 48.59 | G12: 47.78 | H12: 78.33 | I12: 41.67 | J12: 236.69 | K12: 57.7 | L12: 160.11 | M12: 108.91 | O12: =IF('Stock Price'!$I$11="OK",B12/INDEX(B$5:B$1258,'Stock Price'!$I$9)-1,"") -> 0.033190578 | P12: =IF('Stock Price'!$I$11="OK",C12/INDEX(C$5:C$1258,'Stock Price'!$I$9)-1,"") -> 0.0094095445 | Q12: =IF('Stock Price'!$I$11="OK",D12/INDEX(D$5:D$1258,'Stock Price'!$I$9)-1,"") -> 0 | R12: =IF('Stock Price'!$I$11="OK",E12/INDEX(E$5:E$1258,'Stock Price'!$I$9)-1,"") -> 0.013082156 | S12: =IF('Stock Price'!$I$11="OK",F12/INDEX(F$5:F$1258,'Stock Price'!$I$9)-1,"") -> 0.0055877483 | T12: =IF('Stock Price'!$I$11="OK",G12/INDEX(G$5:G$1258,'Stock Price'!$I$9)-1,"") -> 0.034983212 | U12: =IF('Stock Price'!$I$11="OK",H12/INDEX(H$5:H$1258,'Stock Price'!$I$9)-1,"") -> -0.040073529 | V12: =IF('Stock Price'!$I$11="OK",I12/INDEX(I$5:I$1258,'Stock Price'!$I$9)-1,"") -> -0.015359168 | ... Z12: =IF('Stock Price'!$I$11="OK",M12/INDEX(M$5:M$1258,'Stock Price'!$I$9)-1,"") -> -0.0054789517 | AB12: PFE | AC12: ='Stock Price'!V56 -> -0.34310019 | AD12: =IF(AC12="","",AC12-ROW()*0.000000001) -> -0.3431002 | AE12: =IF(AD12="","",COUNTIF($AD$5:$AD$16,">"&AD12)+1) -> 12 | AF12: =IF(AC12="",AB12,AB12&" "&TEXT(AC12,"+0.0%;-0.0%;0.0%")) -> PFE -34.3% | AG12: =IF(AE12="","",INDEX($AK$5:$AK$16,AE12)) -> -0.59124878 | AH12: 8 | AI12: =IF('Stock Price'!$I$11="OK",LARGE($AD$5:$AD$16,AH12),"") -> 0.033812328 | AJ12: =IF('Stock Price'!$I$11="OK",MIN(AI12,AJ11-$AL$5),"") -> -0.37438754 | AK12: =IF('Stock Price'!$I$11="OK",MAX(AJ12,AK13+$AL$5),"") -> 0.33314595
A13: ='Stock Price'!A13 -> 44484 | B13: ='Stock Price'!E13 -> 48.92 | C13: 80.6155 | D13: 118.58 | E13: 48.7625 | F13: 48.85 | G13: 47.885 | H13: 78.33 | I13: 41.49 | J13: 237.88 | K13: 58.36 | L13: 161.3 | M13: 109.33 | O13: =IF('Stock Price'!$I$11="OK",B13/INDEX(B$5:B$1258,'Stock Price'!$I$9)-1,"") -> 0.047537473 | P13: =IF('Stock Price'!$I$11="OK",C13/INDEX(C$5:C$1258,'Stock Price'!$I$9)-1,"") -> 0.018331495 | Q13: =IF('Stock Price'!$I$11="OK",D13/INDEX(D$5:D$1258,'Stock Price'!$I$9)-1,"") -> -0.02 | R13: =IF('Stock Price'!$I$11="OK",E13/INDEX(E$5:E$1258,'Stock Price'!$I$9)-1,"") -> 0.020669806 | S13: =IF('Stock Price'!$I$11="OK",F13/INDEX(F$5:F$1258,'Stock Price'!$I$9)-1,"") -> 0.010968543 | T13: =IF('Stock Price'!$I$11="OK",G13/INDEX(G$5:G$1258,'Stock Price'!$I$9)-1,"") -> 0.037257663 | U13: =IF('Stock Price'!$I$11="OK",H13/INDEX(H$5:H$1258,'Stock Price'!$I$9)-1,"") -> -0.040073529 | V13: =IF('Stock Price'!$I$11="OK",I13/INDEX(I$5:I$1258,'Stock Price'!$I$9)-1,"") -> -0.019612476 | ... Z13: =IF('Stock Price'!$I$11="OK",M13/INDEX(M$5:M$1258,'Stock Price'!$I$9)-1,"") -> -0.0016436855 | AB13: LLY | AC13: ='Stock Price'!V57 -> 3.9489023 | AD13: =IF(AC13="","",AC13-ROW()*0.000000001) -> 3.9489023 | AE13: =IF(AD13="","",COUNTIF($AD$5:$AD$16,">"&AD13)+1) -> 1 | AF13: =IF(AC13="",AB13,AB13&" "&TEXT(AC13,"+0.0%;-0.0%;0.0%")) -> LLY +394.9% | AG13: =IF(AE13="","",INDEX($AK$5:$AK$16,AE13)) -> 3.9489023 | AH13: 9 | AI13: =IF('Stock Price'!$I$11="OK",LARGE($AD$5:$AD$16,AH13),"") -> -0.015593938 | AJ13: =IF('Stock Price'!$I$11="OK",MIN(AI13,AJ12-$AL$5),"") -> -0.60548622 | AK13: =IF('Stock Price'!$I$11="OK",MAX(AJ13,AK14+$AL$5),"") -> 0.10204726
A14: ='Stock Price'!A14 -> 44487 | B14: ='Stock Price'!E14 -> 49.16 | C14: 79.6577 | D14: 120.12 | E14: 48.3125 | F14: 48.03 | G14: 46.615 | H14: 77.15 | I14: 41.32 | J14: 238.98 | K14: 56.94 | L14: 160.12 | M14: 107.43 | O14: =IF('Stock Price'!$I$11="OK",B14/INDEX(B$5:B$1258,'Stock Price'!$I$9)-1,"") -> 0.05267666 | P14: =IF('Stock Price'!$I$11="OK",C14/INDEX(C$5:C$1258,'Stock Price'!$I$9)-1,"") -> 0.0062326074 | Q14: =IF('Stock Price'!$I$11="OK",D14/INDEX(D$5:D$1258,'Stock Price'!$I$9)-1,"") -> -0.0072727273 | R14: =IF('Stock Price'!$I$11="OK",E14/INDEX(E$5:E$1258,'Stock Price'!$I$9)-1,"") -> 0.011250654 | S14: =IF('Stock Price'!$I$11="OK",F14/INDEX(F$5:F$1258,'Stock Price'!$I$9)-1,"") -> -0.0060016556 | T14: =IF('Stock Price'!$I$11="OK",G14/INDEX(G$5:G$1258,'Stock Price'!$I$9)-1,"") -> 0.0097476443 | U14: =IF('Stock Price'!$I$11="OK",H14/INDEX(H$5:H$1258,'Stock Price'!$I$9)-1,"") -> -0.054534314 | V14: =IF('Stock Price'!$I$11="OK",I14/INDEX(I$5:I$1258,'Stock Price'!$I$9)-1,"") -> -0.02362949 | ... Z14: =IF('Stock Price'!$I$11="OK",M14/INDEX(M$5:M$1258,'Stock Price'!$I$9)-1,"") -> -0.018993699 | AB14: BMY | AC14: ='Stock Price'!V58 -> 0.033812342 | AD14: =IF(AC14="","",AC14-ROW()*0.000000001) -> 0.033812328 | AE14: =IF(AD14="","",COUNTIF($AD$5:$AD$16,">"&AD14)+1) -> 8 | AF14: =IF(AC14="",AB14,AB14&" "&TEXT(AC14,"+0.0%;-0.0%;0.0%")) -> BMY +3.4% | AG14: =IF(AE14="","",INDEX($AK$5:$AK$16,AE14)) -> 0.33314595 | AH14: 10 | AI14: =IF('Stock Price'!$I$11="OK",LARGE($AD$5:$AD$16,AH14),"") -> -0.026535264 | AJ14: =IF('Stock Price'!$I$11="OK",MIN(AI14,AJ13-$AL$5),"") -> -0.8365849 | AK14: =IF('Stock Price'!$I$11="OK",MAX(AJ14,AK15+$AL$5),"") -> -0.12905142
A15: ='Stock Price'!A15 -> 44488 | B15: ='Stock Price'!E15 -> 48.55 | C15: 80.4413 | D15: 119.37 | E15: 48.9625 | F15: 48.06 | G15: 47.28 | H15: 79.49 | I15: 42.09 | J15: 242.31 | K15: 57.59 | L15: 163.87 | M15: 107.45 | O15: =IF('Stock Price'!$I$11="OK",B15/INDEX(B$5:B$1258,'Stock Price'!$I$9)-1,"") -> 0.039614561 | P15: =IF('Stock Price'!$I$11="OK",C15/INDEX(C$5:C$1258,'Stock Price'!$I$9)-1,"") -> 0.016131009 | Q15: =IF('Stock Price'!$I$11="OK",D15/INDEX(D$5:D$1258,'Stock Price'!$I$9)-1,"") -> -0.013471074 | R15: =IF('Stock Price'!$I$11="OK",E15/INDEX(E$5:E$1258,'Stock Price'!$I$9)-1,"") -> 0.024856096 | S15: =IF('Stock Price'!$I$11="OK",F15/INDEX(F$5:F$1258,'Stock Price'!$I$9)-1,"") -> -0.0053807947 | T15: =IF('Stock Price'!$I$11="OK",G15/INDEX(G$5:G$1258,'Stock Price'!$I$9)-1,"") -> 0.024152496 | U15: =IF('Stock Price'!$I$11="OK",H15/INDEX(H$5:H$1258,'Stock Price'!$I$9)-1,"") -> -0.025857843 | V15: =IF('Stock Price'!$I$11="OK",I15/INDEX(I$5:I$1258,'Stock Price'!$I$9)-1,"") -> -0.0054347826 | ... Z15: =IF('Stock Price'!$I$11="OK",M15/INDEX(M$5:M$1258,'Stock Price'!$I$9)-1,"") -> -0.018811067 | AB15: JnJ | AC15: ='Stock Price'!V59 -> 0.60439905 | AD15: =IF(AC15="","",AC15-ROW()*0.000000001) -> 0.60439903 | AE15: =IF(AD15="","",COUNTIF($AD$5:$AD$16,">"&AD15)+1) -> 5 | AF15: =IF(AC15="",AB15,AB15&" "&TEXT(AC15,"+0.0%;-0.0%;0.0%")) -> JnJ +60.4% | AG15: =IF(AE15="","",INDEX($AK$5:$AK$16,AE15)) -> 1.026442 | AH15: 11 | AI15: =IF('Stock Price'!$I$11="OK",LARGE($AD$5:$AD$16,AH15),"") -> -0.17384107 | AJ15: =IF('Stock Price'!$I$11="OK",MIN(AI15,AJ14-$AL$5),"") -> -1.0676836 | AK15: =IF('Stock Price'!$I$11="OK",MAX(AJ15,AK16+$AL$5),"") -> -0.3601501
A16: ='Stock Price'!A16 -> 44489 | B16: ='Stock Price'!E16 -> 47.76 | C16: 81.7183 | D16: 122 | E16: 49.325 | F16: 49.05 | G16: 48.175 | H16: 81.07 | I16: 42.8 | J16: 243.72 | K16: 58.07 | L16: 163.78 | M16: 108.41 | O16: =IF('Stock Price'!$I$11="OK",B16/INDEX(B$5:B$1258,'Stock Price'!$I$9)-1,"") -> 0.022698073 | P16: =IF('Stock Price'!$I$11="OK",C16/INDEX(C$5:C$1258,'Stock Price'!$I$9)-1,"") -> 0.032262017 | Q16: =IF('Stock Price'!$I$11="OK",D16/INDEX(D$5:D$1258,'Stock Price'!$I$9)-1,"") -> 0.0082644628 | R16: =IF('Stock Price'!$I$11="OK",E16/INDEX(E$5:E$1258,'Stock Price'!$I$9)-1,"") -> 0.032443747 | S16: =IF('Stock Price'!$I$11="OK",F16/INDEX(F$5:F$1258,'Stock Price'!$I$9)-1,"") -> 0.015107616 | T16: =IF('Stock Price'!$I$11="OK",G16/INDEX(G$5:G$1258,'Stock Price'!$I$9)-1,"") -> 0.043539478 | U16: =IF('Stock Price'!$I$11="OK",H16/INDEX(H$5:H$1258,'Stock Price'!$I$9)-1,"") -> -0.006495098 | V16: =IF('Stock Price'!$I$11="OK",I16/INDEX(I$5:I$1258,'Stock Price'!$I$9)-1,"") -> 0.011342155 | ... Z16: =IF('Stock Price'!$I$11="OK",M16/INDEX(M$5:M$1258,'Stock Price'!$I$9)-1,"") -> -0.010044745 | AB16: ABBV | AC16: ='Stock Price'!V60 -> 1.3999635 | AD16: =IF(AC16="","",AC16-ROW()*0.000000001) -> 1.3999635 | AE16: =IF(AD16="","",COUNTIF($AD$5:$AD$16,">"&AD16)+1) -> 2 | AF16: =IF(AC16="",AB16,AB16&" "&TEXT(AC16,"+0.0%;-0.0%;0.0%")) -> ABBV +140.0% | AG16: =IF(AE16="","",INDEX($AK$5:$AK$16,AE16)) -> 1.719738 | AH16: 12 | AI16: =IF('Stock Price'!$I$11="OK",LARGE($AD$5:$AD$16,AH16),"") -> -0.3431002 | AJ16: =IF('Stock Price'!$I$11="OK",MIN(AI16,AJ15-$AL$5),"") -> -1.2987823 | AK16: =IF('Stock Price'!$I$11="OK",MAX(AJ16,$AM$5),"") -> -0.59124878
A17: ='Stock Price'!A17 -> 44490 | B17: ='Stock Price'!E17 -> 48.84 | C17: 81.9118 | D17: 122.4 | E17: 49.4375 | F17: 49.21 | G17: 48.19 | H17: 81.17 | I17: 42.86 | J17: 241.17 | K17: 57.81 | L17: 163.4 | M17: 108.76 | O17: =IF('Stock Price'!$I$11="OK",B17/INDEX(B$5:B$1258,'Stock Price'!$I$9)-1,"") -> 0.045824411 | P17: =IF('Stock Price'!$I$11="OK",C17/INDEX(C$5:C$1258,'Stock Price'!$I$9)-1,"") -> 0.034706301 | Q17: =IF('Stock Price'!$I$11="OK",D17/INDEX(D$5:D$1258,'Stock Price'!$I$9)-1,"") -> 0.011570248 | R17: =IF('Stock Price'!$I$11="OK",E17/INDEX(E$5:E$1258,'Stock Price'!$I$9)-1,"") -> 0.034798535 | S17: =IF('Stock Price'!$I$11="OK",F17/INDEX(F$5:F$1258,'Stock Price'!$I$9)-1,"") -> 0.018418874 | T17: =IF('Stock Price'!$I$11="OK",G17/INDEX(G$5:G$1258,'Stock Price'!$I$9)-1,"") -> 0.043864399 | U17: =IF('Stock Price'!$I$11="OK",H17/INDEX(H$5:H$1258,'Stock Price'!$I$9)-1,"") -> -0.0052696078 | V17: =IF('Stock Price'!$I$11="OK",I17/INDEX(I$5:I$1258,'Stock Price'!$I$9)-1,"") -> 0.012759924 | ... Z17: =IF('Stock Price'!$I$11="OK",M17/INDEX(M$5:M$1258,'Stock Price'!$I$9)-1,"") -> -0.0068486896
A18: ='Stock Price'!A18 -> 44491 | B18: ='Stock Price'!E18 -> 48.74 | C18: 82.1537 | D18: 123.775 | E18: 49.7125 | F18: 49.92 | G18: 48.32 | H18: 81.15 | I18: 43.16 | J18: 243.75 | K18: 57.6 | L18: 163.72 | M18: 109.14 | O18: =IF('Stock Price'!$I$11="OK",B18/INDEX(B$5:B$1258,'Stock Price'!$I$9)-1,"") -> 0.043683084 | P18: =IF('Stock Price'!$I$11="OK",C18/INDEX(C$5:C$1258,'Stock Price'!$I$9)-1,"") -> 0.037761971 | Q18: =IF('Stock Price'!$I$11="OK",D18/INDEX(D$5:D$1258,'Stock Price'!$I$9)-1,"") -> 0.022933884 | R18: =IF('Stock Price'!$I$11="OK",E18/INDEX(E$5:E$1258,'Stock Price'!$I$9)-1,"") -> 0.040554683 | S18: =IF('Stock Price'!$I$11="OK",F18/INDEX(F$5:F$1258,'Stock Price'!$I$9)-1,"") -> 0.033112583 | T18: =IF('Stock Price'!$I$11="OK",G18/INDEX(G$5:G$1258,'Stock Price'!$I$9)-1,"") -> 0.046680386 | U18: =IF('Stock Price'!$I$11="OK",H18/INDEX(H$5:H$1258,'Stock Price'!$I$9)-1,"") -> -0.0055147059 | V18: =IF('Stock Price'!$I$11="OK",I18/INDEX(I$5:I$1258,'Stock Price'!$I$9)-1,"") -> 0.019848771 | ... Z18: =IF('Stock Price'!$I$11="OK",M18/INDEX(M$5:M$1258,'Stock Price'!$I$9)-1,"") -> -0.0033786869
A19: ='Stock Price'!A19 -> 44494 | B19: ='Stock Price'!E19 -> 48.48 | C19: 80.6445 | D19: 124.82 | E19: 49.7625 | F19: 49.79 | G19: 48.455 | H19: 81.66 | I19: 43.15 | J19: 245.05 | K19: 57.81 | L19: 164.08 | M19: 108.5 | O19: =IF('Stock Price'!$I$11="OK",B19/INDEX(B$5:B$1258,'Stock Price'!$I$9)-1,"") -> 0.038115632 | P19: =IF('Stock Price'!$I$11="OK",C19/INDEX(C$5:C$1258,'Stock Price'!$I$9)-1,"") -> 0.018697822 | Q19: =IF('Stock Price'!$I$11="OK",D19/INDEX(D$5:D$1258,'Stock Price'!$I$9)-1,"") -> 0.031570248 | R19: =IF('Stock Price'!$I$11="OK",E19/INDEX(E$5:E$1258,'Stock Price'!$I$9)-1,"") -> 0.041601256 | S19: =IF('Stock Price'!$I$11="OK",F19/INDEX(F$5:F$1258,'Stock Price'!$I$9)-1,"") -> 0.030422185 | T19: =IF('Stock Price'!$I$11="OK",G19/INDEX(G$5:G$1258,'Stock Price'!$I$9)-1,"") -> 0.049604679 | U19: =IF('Stock Price'!$I$11="OK",H19/INDEX(H$5:H$1258,'Stock Price'!$I$9)-1,"") -> 0.00073529412 | V19: =IF('Stock Price'!$I$11="OK",I19/INDEX(I$5:I$1258,'Stock Price'!$I$9)-1,"") -> 0.019612476 | ... Z19: =IF('Stock Price'!$I$11="OK",M19/INDEX(M$5:M$1258,'Stock Price'!$I$9)-1,"") -> -0.009222902
A20: ='Stock Price'!A20 -> 44495 | B20: ='Stock Price'!E20 -> 48.53 | C20: 82.0763 | D20: 123.13 | E20: 50.225 | F20: 49.96 | G20: 48.79 | H20: 82.25 | I20: 43.56 | J20: 248.44 | K20: 58.24 | L20: 165.75 | M20: 109.49 | O20: =IF('Stock Price'!$I$11="OK",B20/INDEX(B$5:B$1258,'Stock Price'!$I$9)-1,"") -> 0.039186296 | P20: =IF('Stock Price'!$I$11="OK",C20/INDEX(C$5:C$1258,'Stock Price'!$I$9)-1,"") -> 0.036784258 | Q20: =IF('Stock Price'!$I$11="OK",D20/INDEX(D$5:D$1258,'Stock Price'!$I$9)-1,"") -> 0.017603306 | R20: =IF('Stock Price'!$I$11="OK",E20/INDEX(E$5:E$1258,'Stock Price'!$I$9)-1,"") -> 0.051282051 | S20: =IF('Stock Price'!$I$11="OK",F20/INDEX(F$5:F$1258,'Stock Price'!$I$9)-1,"") -> 0.033940397 | T20: =IF('Stock Price'!$I$11="OK",G20/INDEX(G$5:G$1258,'Stock Price'!$I$9)-1,"") -> 0.056861259 | U20: =IF('Stock Price'!$I$11="OK",H20/INDEX(H$5:H$1258,'Stock Price'!$I$9)-1,"") -> 0.0079656863 | V20: =IF('Stock Price'!$I$11="OK",I20/INDEX(I$5:I$1258,'Stock Price'!$I$9)-1,"") -> 0.029300567 | ... Z20: =IF('Stock Price'!$I$11="OK",M20/INDEX(M$5:M$1258,'Stock Price'!$I$9)-1,"") -> -0.00018263172
A21: ='Stock Price'!A21 -> 44496 | B21: ='Stock Price'!E21 -> 48.04 | C21: 80.035 | D21: 122.81 | E21: 50.525 | F21: 49.57 | G21: 48.595 | H21: 81.54 | I21: 42.97 | J21: 250.17 | K21: 56.49 | L21: 163.74 | M21: 108.4 | O21: =IF('Stock Price'!$I$11="OK",B21/INDEX(B$5:B$1258,'Stock Price'!$I$9)-1,"") -> 0.02869379 | P21: =IF('Stock Price'!$I$11="OK",C21/INDEX(C$5:C$1258,'Stock Price'!$I$9)-1,"") -> 0.010998645 | Q21: =IF('Stock Price'!$I$11="OK",D21/INDEX(D$5:D$1258,'Stock Price'!$I$9)-1,"") -> 0.014958678 | R21: =IF('Stock Price'!$I$11="OK",E21/INDEX(E$5:E$1258,'Stock Price'!$I$9)-1,"") -> 0.057561486 | S21: =IF('Stock Price'!$I$11="OK",F21/INDEX(F$5:F$1258,'Stock Price'!$I$9)-1,"") -> 0.025869205 | T21: =IF('Stock Price'!$I$11="OK",G21/INDEX(G$5:G$1258,'Stock Price'!$I$9)-1,"") -> 0.052637279 | U21: =IF('Stock Price'!$I$11="OK",H21/INDEX(H$5:H$1258,'Stock Price'!$I$9)-1,"") -> -0.00073529412 | V21: =IF('Stock Price'!$I$11="OK",I21/INDEX(I$5:I$1258,'Stock Price'!$I$9)-1,"") -> 0.015359168 | ... Z21: =IF('Stock Price'!$I$11="OK",M21/INDEX(M$5:M$1258,'Stock Price'!$I$9)-1,"") -> -0.010136061
A22: ='Stock Price'!A22 -> 44497 | B22: ='Stock Price'!E22 -> 48.75 | C22: 80.5961 | D22: 127.25 | E22: 52.65 | F22: 50.14 | G22: 48.735 | H22: 86.55 | I22: 43.18 | J22: 253.35 | K22: 57.13 | L22: 162.85 | M22: 109.67 | O22: =IF('Stock Price'!$I$11="OK",B22/INDEX(B$5:B$1258,'Stock Price'!$I$9)-1,"") -> 0.043897216 | P22: =IF('Stock Price'!$I$11="OK",C22/INDEX(C$5:C$1258,'Stock Price'!$I$9)-1,"") -> 0.018086435 | Q22: =IF('Stock Price'!$I$11="OK",D22/INDEX(D$5:D$1258,'Stock Price'!$I$9)-1,"") -> 0.051652893 | R22: =IF('Stock Price'!$I$11="OK",E22/INDEX(E$5:E$1258,'Stock Price'!$I$9)-1,"") -> 0.10204082 | S22: =IF('Stock Price'!$I$11="OK",F22/INDEX(F$5:F$1258,'Stock Price'!$I$9)-1,"") -> 0.037665563 | T22: =IF('Stock Price'!$I$11="OK",G22/INDEX(G$5:G$1258,'Stock Price'!$I$9)-1,"") -> 0.05566988 | U22: =IF('Stock Price'!$I$11="OK",H22/INDEX(H$5:H$1258,'Stock Price'!$I$9)-1,"") -> 0.060661765 | V22: =IF('Stock Price'!$I$11="OK",I22/INDEX(I$5:I$1258,'Stock Price'!$I$9)-1,"") -> 0.020321361 | ... Z22: =IF('Stock Price'!$I$11="OK",M22/INDEX(M$5:M$1258,'Stock Price'!$I$9)-1,"") -> 0.0014610538
A23: ='Stock Price'!A23 -> 44498 | B23: ='Stock Price'!E23 -> 48.33 | C23: 80.064 | D23: 125.275 | E23: 52.9125 | F23: 50.43 | G23: 48.67 | H23: 88.05 | I23: 43.74 | J23: 254.76 | K23: 58.4 | L23: 162.88 | M23: 114.67 | O23: =IF('Stock Price'!$I$11="OK",B23/INDEX(B$5:B$1258,'Stock Price'!$I$9)-1,"") -> 0.03490364 | P23: =IF('Stock Price'!$I$11="OK",C23/INDEX(C$5:C$1258,'Stock Price'!$I$9)-1,"") -> 0.011364971 | Q23: =IF('Stock Price'!$I$11="OK",D23/INDEX(D$5:D$1258,'Stock Price'!$I$9)-1,"") -> 0.035330579 | R23: =IF('Stock Price'!$I$11="OK",E23/INDEX(E$5:E$1258,'Stock Price'!$I$9)-1,"") -> 0.10753532 | S23: =IF('Stock Price'!$I$11="OK",F23/INDEX(F$5:F$1258,'Stock Price'!$I$9)-1,"") -> 0.043667219 | T23: =IF('Stock Price'!$I$11="OK",G23/INDEX(G$5:G$1258,'Stock Price'!$I$9)-1,"") -> 0.054261887 | U23: =IF('Stock Price'!$I$11="OK",H23/INDEX(H$5:H$1258,'Stock Price'!$I$9)-1,"") -> 0.079044118 | V23: =IF('Stock Price'!$I$11="OK",I23/INDEX(I$5:I$1258,'Stock Price'!$I$9)-1,"") -> 0.033553875 | ... Z23: =IF('Stock Price'!$I$11="OK",M23/INDEX(M$5:M$1258,'Stock Price'!$I$9)-1,"") -> 0.047118985
A24: ='Stock Price'!A24 -> 44501 | B24: ='Stock Price'!E24 -> 49.34 | C24: 81.312 | D24: 127.17 | E24: 53.2375 | F24: 51.3 | G24: 49.48 | H24: 87.84 | I24: 43.64 | J24: 249.31 | K24: 58.68 | L24: 163.02 | M24: 114.81 | O24: =IF('Stock Price'!$I$11="OK",B24/INDEX(B$5:B$1258,'Stock Price'!$I$9)-1,"") -> 0.056531049 | P24: =IF('Stock Price'!$I$11="OK",C24/INDEX(C$5:C$1258,'Stock Price'!$I$9)-1,"") -> 0.027129653 | Q24: =IF('Stock Price'!$I$11="OK",D24/INDEX(D$5:D$1258,'Stock Price'!$I$9)-1,"") -> 0.050991736 | R24: =IF('Stock Price'!$I$11="OK",E24/INDEX(E$5:E$1258,'Stock Price'!$I$9)-1,"") -> 0.11433804 | S24: =IF('Stock Price'!$I$11="OK",F24/INDEX(F$5:F$1258,'Stock Price'!$I$9)-1,"") -> 0.061672185 | T24: =IF('Stock Price'!$I$11="OK",G24/INDEX(G$5:G$1258,'Stock Price'!$I$9)-1,"") -> 0.071807646 | U24: =IF('Stock Price'!$I$11="OK",H24/INDEX(H$5:H$1258,'Stock Price'!$I$9)-1,"") -> 0.076470588 | V24: =IF('Stock Price'!$I$11="OK",I24/INDEX(I$5:I$1258,'Stock Price'!$I$9)-1,"") -> 0.031190926 | ... Z24: =IF('Stock Price'!$I$11="OK",M24/INDEX(M$5:M$1258,'Stock Price'!$I$9)-1,"") -> 0.048397407
A25: ='Stock Price'!A25 -> 44502 | B25: ='Stock Price'!E25 -> 50.07 | C25: 81.0218 | D25: 126.45 | E25: 53.5 | F25: 51.93 | G25: 49.985 | H25: 89.02 | I25: 45.45 | J25: 256.85 | K25: 58.63 | L25: 165.59 | M25: 116.53 | O25: =IF('Stock Price'!$I$11="OK",B25/INDEX(B$5:B$1258,'Stock Price'!$I$9)-1,"") -> 0.072162741 | P25: =IF('Stock Price'!$I$11="OK",C25/INDEX(C$5:C$1258,'Stock Price'!$I$9)-1,"") -> 0.023463859 | Q25: =IF('Stock Price'!$I$11="OK",D25/INDEX(D$5:D$1258,'Stock Price'!$I$9)-1,"") -> 0.045041322 | R25: =IF('Stock Price'!$I$11="OK",E25/INDEX(E$5:E$1258,'Stock Price'!$I$9)-1,"") -> 0.11983255 | S25: =IF('Stock Price'!$I$11="OK",F25/INDEX(F$5:F$1258,'Stock Price'!$I$9)-1,"") -> 0.074710265 | T25: =IF('Stock Price'!$I$11="OK",G25/INDEX(G$5:G$1258,'Stock Price'!$I$9)-1,"") -> 0.08274667 | U25: =IF('Stock Price'!$I$11="OK",H25/INDEX(H$5:H$1258,'Stock Price'!$I$9)-1,"") -> 0.090931373 | V25: =IF('Stock Price'!$I$11="OK",I25/INDEX(I$5:I$1258,'Stock Price'!$I$9)-1,"") -> 0.073960302 | ... Z25: =IF('Stock Price'!$I$11="OK",M25/INDEX(M$5:M$1258,'Stock Price'!$I$9)-1,"") -> 0.064103735
A26: ='Stock Price'!A26 -> 44503 | B26: ='Stock Price'!E26 -> 50.45 | C26: 80.867 | D26: 129 | E26: 54.4125 | F26: 52.35 | G26: 50.25 | H26: 88.68 | I26: 44.82 | J26: 266.26 | K26: 59.36 | L26: 165.06 | M26: 117.57 | O26: =IF('Stock Price'!$I$11="OK",B26/INDEX(B$5:B$1258,'Stock Price'!$I$9)-1,"") -> 0.080299786 | P26: =IF('Stock Price'!$I$11="OK",C26/INDEX(C$5:C$1258,'Stock Price'!$I$9)-1,"") -> 0.021508432 | Q26: =IF('Stock Price'!$I$11="OK",D26/INDEX(D$5:D$1258,'Stock Price'!$I$9)-1,"") -> 0.066115702 | R26: =IF('Stock Price'!$I$11="OK",E26/INDEX(E$5:E$1258,'Stock Price'!$I$9)-1,"") -> 0.1389325 | S26: =IF('Stock Price'!$I$11="OK",F26/INDEX(F$5:F$1258,'Stock Price'!$I$9)-1,"") -> 0.083402318 | T26: =IF('Stock Price'!$I$11="OK",G26/INDEX(G$5:G$1258,'Stock Price'!$I$9)-1,"") -> 0.088486949 | U26: =IF('Stock Price'!$I$11="OK",H26/INDEX(H$5:H$1258,'Stock Price'!$I$9)-1,"") -> 0.086764706 | V26: =IF('Stock Price'!$I$11="OK",I26/INDEX(I$5:I$1258,'Stock Price'!$I$9)-1,"") -> 0.059073724 | ... Z26: =IF('Stock Price'!$I$11="OK",M26/INDEX(M$5:M$1258,'Stock Price'!$I$9)-1,"") -> 0.073600584
A27: ='Stock Price'!A27 -> 44504 | B27: ='Stock Price'!E27 -> 51.02 | C27: 80.9637 | D27: 129.92 | E27: 53.75 | F27: 51.79 | G27: 49.95 | H27: 90.54 | I27: 43.85 | J27: 271 | K27: 59.25 | L27: 164.6 | M27: 117.06 | O27: =IF('Stock Price'!$I$11="OK",B27/INDEX(B$5:B$1258,'Stock Price'!$I$9)-1,"") -> 0.092505353 | P27: =IF('Stock Price'!$I$11="OK",C27/INDEX(C$5:C$1258,'Stock Price'!$I$9)-1,"") -> 0.022729943 | Q27: =IF('Stock Price'!$I$11="OK",D27/INDEX(D$5:D$1258,'Stock Price'!$I$9)-1,"") -> 0.073719008 | R27: =IF('Stock Price'!$I$11="OK",E27/INDEX(E$5:E$1258,'Stock Price'!$I$9)-1,"") -> 0.12506541 | S27: =IF('Stock Price'!$I$11="OK",F27/INDEX(F$5:F$1258,'Stock Price'!$I$9)-1,"") -> 0.071812914 | T27: =IF('Stock Price'!$I$11="OK",G27/INDEX(G$5:G$1258,'Stock Price'!$I$9)-1,"") -> 0.081988519 | U27: =IF('Stock Price'!$I$11="OK",H27/INDEX(H$5:H$1258,'Stock Price'!$I$9)-1,"") -> 0.10955882 | V27: =IF('Stock Price'!$I$11="OK",I27/INDEX(I$5:I$1258,'Stock Price'!$I$9)-1,"") -> 0.036153119 | ... Z27: =IF('Stock Price'!$I$11="OK",M27/INDEX(M$5:M$1258,'Stock Price'!$I$9)-1,"") -> 0.068943475
A28: ='Stock Price'!A28 -> 44505 | B28: ='Stock Price'!E28 -> 50.2 | C28: 80.925 | D28: 125.47 | E28: 54.3625 | F28: 51.29 | G28: 49.725 | H28: 81.61 | I28: 48.61 | J28: 265 | K28: 59.45 | L28: 163.43 | M28: 117.18 | O28: =IF('Stock Price'!$I$11="OK",B28/INDEX(B$5:B$1258,'Stock Price'!$I$9)-1,"") -> 0.074946467 | P28: =IF('Stock Price'!$I$11="OK",C28/INDEX(C$5:C$1258,'Stock Price'!$I$9)-1,"") -> 0.022241086 | Q28: =IF('Stock Price'!$I$11="OK",D28/INDEX(D$5:D$1258,'Stock Price'!$I$9)-1,"") -> 0.036942149 | R28: =IF('Stock Price'!$I$11="OK",E28/INDEX(E$5:E$1258,'Stock Price'!$I$9)-1,"") -> 0.13788592 | S28: =IF('Stock Price'!$I$11="OK",F28/INDEX(F$5:F$1258,'Stock Price'!$I$9)-1,"") -> 0.061465232 | T28: =IF('Stock Price'!$I$11="OK",G28/INDEX(G$5:G$1258,'Stock Price'!$I$9)-1,"") -> 0.077114697 | U28: =IF('Stock Price'!$I$11="OK",H28/INDEX(H$5:H$1258,'Stock Price'!$I$9)-1,"") -> 0.00012254902 | V28: =IF('Stock Price'!$I$11="OK",I28/INDEX(I$5:I$1258,'Stock Price'!$I$9)-1,"") -> 0.14862949 | ... Z28: =IF('Stock Price'!$I$11="OK",M28/INDEX(M$5:M$1258,'Stock Price'!$I$9)-1,"") -> 0.070039266
